Workbook
Name CatReceitas: '⚙️ Config'!$B$7:$B$18
Name CatDespesas: '⚙️ Config'!$C$7:$C$18
Name FormasPag: '⚙️ Config'!$D$7:$D$18
Name ListaContas: '⚙️ Config'!$E$7:$E$18
Name ListaCartoes: '⚙️ Config'!$F$7:$F$18
Name ListaMeses: '⚙️ Config'!$G$7:$G$18
Name ListaAnos: '⚙️ Config'!$I$7:$I$18

Sheet 📊 Dashboard
B1: 📊 Início | C1: 💰 Receitas | D1: 💸 Despesas | E1: 🏦 Contas | F1: 💳 Cartões | G1: 🎯 Metas | H1: 📅 Orçamento | I1: 📈 Relatórios | J1: 🔔 Alertas | K1: ⚙️ Config
B3: 💚 PAINEL FINANCEIRO PESSOAL | I3: Mês: | J3: 7 | K3: Ano: | L3: 2026
B4: ="Visão de "&INDEX('⚙️ Config'!$H$7:$H$18,$J$3)&" de "&$L$3
B6: 💼 SALDO ATUAL | D6: 💰 RECEITAS DO MÊS | F6: 💸 DESPESAS DO MÊS | H6: 🐷 ECONOMIA DO MÊS | J6: 📊 % DE GASTOS
B7: ='🏦 Contas'!$G$15 | D7: =SUMIFS('💰 Receitas'!$D:$D,'💰 Receitas'!$A:$A,">="&DATE('📊 Dashboard'!$L$3,'📊 Dashboard'!$J$3,1),'💰 Receitas'!$A:$A,"<="&EOMONTH(DATE('📊 Dashboard'!$L$3,'📊 Dashboard'!$J$3,1),0)) | F7: =SUMIFS('💸 Despesas'!$D:$D,'💸 Despesas'!$A:$A,">="&DATE('📊 Dashboard'!$L$3,'📊 Dashboard'!$J$3,1),'💸 Despesas'!$A:$A,"<="&EOMONTH(DATE('📊 Dashboard'!$L$3,'📊 Dashboard'!$J$3,1),0)) | H7: =SUMIFS('💰 Receitas'!$D:$D,'💰 Receitas'!$A:$A,">="&DATE('📊 Dashboard'!$L$3,'📊 Dashboard'!$J$3,1),'💰 Receitas'!$A:$A,"<="&EOMONTH(DATE('📊 Dashboard'!$L$3,'📊 Dashboard'!$J$3,1),0))-SUMIFS('💸 Despesas'!$D:$D,'💸 Despesas'!$A:$A,">="&DATE('📊 Dashboard'!$L$3,'📊 Dashboard'!$J$3,1),'💸 Despesas'!$A:$A,"<="&EOMONTH(DATE('📊 Dashboard'!$L$3,'📊 Dashboard'!$J$3,1),0)) | J7: =IFERROR(SUMIFS('💸 Despesas'!$D:$D,'💸 Despesas'!$A:$A,">="&DATE('📊 Dashboard'!$L$3,'📊 Dashboard'!$J$3,1),'💸 Despesas'!$A:$A,"<="&EOMONTH(DATE('📊 Dashboard'!$L$3,'📊 Dashboard'!$J$3,1),0))/SUMIFS('💰 Receitas'!$D:$D,'💰 Receitas'!$A:$A,">="&DATE('📊 Dashboard'!$L$3,'📊 Dashboard'!$J$3,1),'💰 Receitas'!$A:$A,"<="&EOMONTH(DATE('📊 Dashboard'!$L$3,'📊 Dashboard'!$J$3,1),0)),0)
B8: ="Somando todas as contas" | D8: ="Entradas do período" | F8: ="Saídas do período" | H8: =IF(SUMIFS('💰 Receitas'!$D:$D,'💰 Receitas'!$A:$A,">="&DATE('📊 Dashboard'!$L$3,'📊 Dashboard'!$J$3,1),'💰 Receitas'!$A:$A,"<="&EOMONTH(DATE('📊 Dashboard'!$L$3,'📊 Dashboard'!$J$3,1),0))=0,"","Taxa de poupança: "&TEXT((SUMIFS('💰 Receitas'!$D:$D,'💰 Receitas'!$A:$A,">="&DATE('📊 Dashboard'!$L$3,'📊 Dashboard'!$J$3,1),'💰 Receitas'!$A:$A,"<="&EOMONTH(DATE('📊 Dashboard'!$L$3,'📊 Dashboard'!$J$3,1),0))-SUMIFS('💸 Despesas'!$D:$D,'💸 Despesas'!$A:$A,">="&DATE('📊 Dashboard'!$L$3,'📊 Dashboard'!$J$3,1),'💸 Despesas'!$A:$A,"<="&EOMONTH(DATE('📊 Dashboard'!$L$3,'📊 Dashboard'!$J$3,1),0)))/SUMIFS('💰 Receitas'!$D:$D,'💰 Receitas'!$A:$A,">="&DATE('📊 Dashboard'!$L$3,'📊 Dashboard'!$J$3,1),'💰 Receitas'!$A:$A,"<="&EOMONTH(DATE('📊 Dashboard'!$L$3,'📊 Dashboard'!$J$3,1),0)),"0%")) | J8: =IF($J$7>0.9,"🚨 Gastos muito altos",IF($J$7>0.7,"⚠️ Atenção aos gastos","✅ Sob controle"))
B10: =IF(SUMIFS('💰 Receitas'!$D:$D,'💰 Receitas'!$A:$A,">="&DATE('📊 Dashboard'!$L$3,'📊 Dashboard'!$J$3,1),'💰 Receitas'!$A:$A,"<="&EOMONTH(DATE('📊 Dashboard'!$L$3,'📊 Dashboard'!$J$3,1),0))=0,"ℹ️ Nenhuma receita registrada neste mês.",IF(SUMIFS('💰 Receitas'!$D:$D,'💰 Receitas'!$A:$A,">="&DATE('📊 Dashboard'!$L$3,'📊 Dashboard'!$J$3,1),'💰 Receitas'!$A:$A,"<="&EOMONTH(DATE('📊 Dashboard'!$L$3,'📊 Dashboard'!$J$3,1),0))-SUMIFS('💸 Despesas'!$D:$D,'💸 Despesas'!$A:$A,">="&DATE('📊 Dashboard'!$L$3,'📊 Dashboard'!$J$3,1),'💸 Despesas'!$A:$A,"<="&EOMONTH(DATE('📊 Dashboard'!$L$3,'📊 Dashboard'!$J$3,1),0))<0,"🔴 CRÍTICO: você gastou mais do que ganhou neste mês!",IF(SUMIFS('💰 Receitas'!$D:$D,'💰 Receitas'!$A:$A,">="&DATE('📊 Dashboard'!$L$3,'📊 Dashboard'!$J$3,1),'💰 Receitas'!$A:$A,"<="&EOMONTH(DATE('📊 Dashboard'!$L$3,'📊 Dashboard'!$J$3,1),0))-SUMIFS('💸 Despesas'!$D:$D,'💸 Despesas'!$A:$A,">="&DATE('📊 Dashboard'!$L$3,'📊 Dashboard'!$J$3,1),'💸 Despesas'!$A:$A,"<="&EOMONTH(DATE('📊 Dashboard'!$L$3,'📊 Dashboard'!$J$3,1),0))<0.2*SUMIFS('💰 Receitas'!$D:$D,'💰 Receitas'!$A:$A,">="&DATE('📊 Dashboard'!$L$3,'📊 Dashboard'!$J$3,1),'💰 Receitas'!$A:$A,"<="&EOMONTH(DATE('📊 Dashboard'!$L$3,'📊 Dashboard'!$J$3,1),0)),"🟡 ATENÇÃO: economia abaixo de 20% da renda.","🟢 EXCELENTE: você está economizando mais de 20% da renda!")))
B12: 🚨 Orçamentos estourados | D12: ='🔔 Alertas'!$E$7 | E12: ⏰ Contas a vencer (7 dias) | G12: ='🔔 Alertas'!$E$8 | H12: 🔴 Contas vencidas | J12: ='🔔 Alertas'!$E$9 | K12: 🎯 Metas atingidas | M12: ='🔔 Alertas'!$E$10
B13: ="👉 Detalhes na aba 🔔 Alertas"

Sheet 💰 Receitas
B1: 📊 Início | C1: 💰 Receitas | D1: 💸 Despesas | E1: 🏦 Contas | F1: 💳 Cartões | G1: 🎯 Metas | H1: 📅 Orçamento | I1: 📈 Relatórios | J1: 🔔 Alertas | K1: ⚙️ Config
B3: 💰 Controle de Receitas | F3: ="Total recebido: "&TEXT(SUMIFS($D$5:$D$204,$G$5:$G$204,"Recebido")/1000,"0.0")&" mil | Pendente: "&TEXT(SUMIFS($D$5:$D$204,$G$5:$G$204,"Pendente")/1000,"0.0")&" mil"
A4: Data | B4: Descrição | C4: Categoria | D4: Valor | E4: Forma de Recebimento | F4: Conta | G4: Status
A5: 46027 | B5: Salário mensal | C5: Salário | D5: 4800 | E5: Transferência | F5: Itaú | G5: Recebido
A6: 46040 | B6: Projeto de site — freelance | C6: Freelance | D6: 800 | E6: Pix | F6: Nubank | G6: Recebido
A7: 46058 | B7: Salário mensal | C7: Salário | D7: 4800 | E7: Transferência | F7: Itaú | G7: Recebido
A8: 46063 | B8: Dividendos de FIIs | C8: Investimentos | D8: 130 | E8: Transferência | F8: Inter | G8: Recebido
A9: 46086 | B9: Salário mensal | C9: Salário | D9: 4800 | E9: Transferência | F9: Itaú | G9: Recebido
A10: 46091 | B10: Dividendos de FIIs | C10: Investimentos | D10: 145 | E10: Transferência | F10: Inter | G10: Recebido
A11: 46103 | B11: Consultoria de marketing | C11: Freelance | D11: 1200 | E11: Pix | F11: Nubank | G11: Recebido
A12: 46117 | B12: Salário mensal | C12: Salário | D12: 4800 | E12: Transferência | F12: Itaú | G12: Recebido
A13: 46122 | B13: Dividendos de FIIs | C13: Investimentos | D13: 150 | E13: Transferência | F13: Inter | G13: Recebido
A14: 46147 | B14: Salário mensal | C14: Salário | D14: 4800 | E14: Transferência | F14: Itaú | G14: Recebido
A15: 46152 | B15: Dividendos de FIIs | C15: Investimentos | D15: 138 | E15: Transferência | F15: Inter | G15: Recebido
A16: 46157 | B16: Criação de logotipo | C16: Freelance | D16: 950 | E16: Pix | F16: Nubank | G16: Recebido
... A21: 46223 | B21: Manutenção de site | C21: Freelance | D21: 600 | E21: Pix | F21: Nubank | G21: Pendente

Sheet 💸 Despesas
B1: 📊 Início | C1: 💰 Receitas | D1: 💸 Despesas | E1: 🏦 Contas | F1: 💳 Cartões | G1: 🎯 Metas | H1: 📅 Orçamento | I1: 📈 Relatórios | J1: 🔔 Alertas | K1: ⚙️ Config
B3: 💸 Controle de Despesas | F3: ="Em aberto: "&COUNTIFS($I$5:$I$204,"Não")&" conta(s) não paga(s)"
A4: Data | B4: Descrição | C4: Categoria | D4: Valor | E4: Forma de Pagamento | F4: Cartão | G4: Parcelas | H4: Vencimento | I4: Pago | J4: Conta | K4: •
A5: 46025 | B5: Energia elétrica | C5: Contas Fixas | D5: 175 | E5: Pix | H5: 46030 | I5: Sim | J5: Itaú | K5: =IF(AND($I5="Não",$H5<>"",$H5<=TODAY()+7),COUNTIFS($H$5:$H$204,"<"&$H5,$I$5:$I$204,"Não",$H$5:$H$204,"<="&TODAY()+7)+COUNTIFS($H$5:$H5,$H5,$I$5:$I5,"Não"),"")
A6: 46026 | B6: Academia | C6: Saúde | D6: 90 | E6: Débito | H6: 46027 | I6: Sim | J6: Nubank | K6: =IF(AND($I6="Não",$H6<>"",$H6<=TODAY()+7),COUNTIFS($H$5:$H$204,"<"&$H6,$I$5:$I$204,"Não",$H$5:$H$204,"<="&TODAY()+7)+COUNTIFS($H$5:$H6,$H6,$I$5:$I6,"Não"),"")
A7: 46028 | B7: Streaming (Netflix + Spotify) | C7: Assinaturas | D7: 55 | E7: Crédito | F7: Nubank | H7: 46058 | I7: Sim | J7: Nubank | K7: =IF(AND($I7="Não",$H7<>"",$H7<=TODAY()+7),COUNTIFS($H$5:$H$204,"<"&$H7,$I$5:$I$204,"Não",$H$5:$H$204,"<="&TODAY()+7)+COUNTIFS($H$5:$H7,$H7,$I$5:$I7,"Não"),"")
A8: 46028 | B8: Aporte em investimentos | C8: Investimentos | D8: 500 | E8: Transferência | H8: 46028 | I8: Sim | J8: Itaú | K8: =IF(AND($I8="Não",$H8<>"",$H8<=TODAY()+7),COUNTIFS($H$5:$H$204,"<"&$H8,$I$5:$I$204,"Não",$H$5:$H$204,"<="&TODAY()+7)+COUNTIFS($H$5:$H8,$H8,$I$5:$I8,"Não"),"")
A9: 46030 | B9: Aluguel + condomínio | C9: Moradia | D9: 1500 | E9: Boleto | H9: 46032 | I9: Sim | J9: Itaú | K9: =IF(AND($I9="Não",$H9<>"",$H9<=TODAY()+7),COUNTIFS($H$5:$H$204,"<"&$H9,$I$5:$I$204,"Não",$H$5:$H$204,"<="&TODAY()+7)+COUNTIFS($H$5:$H9,$H9,$I$5:$I9,"Não"),"")
A10: 46032 | B10: Plano de celular | C10: Contas Fixas | D10: 60 | E10: Débito | H10: 46034 | I10: Sim | J10: Nubank | K10: =IF(AND($I10="Não",$H10<>"",$H10<=TODAY()+7),COUNTIFS($H$5:$H$204,"<"&$H10,$I$5:$I$204,"Não",$H$5:$H$204,"<="&TODAY()+7)+COUNTIFS($H$5:$H10,$H10,$I$5:$I10,"Não"),"")
A11: 46034 | B11: Supermercado do mês | C11: Alimentação | D11: 620 | E11: Crédito | F11: Nubank | H11: 46058 | I11: Sim | J11: Nubank | K11: =IF(AND($I11="Não",$H11<>"",$H11<=TODAY()+7),COUNTIFS($H$5:$H$204,"<"&$H11,$I$5:$I$204,"Não",$H$5:$H$204,"<="&TODAY()+7)+COUNTIFS($H$5:$H11,$H11,$I$5:$I11,"Não"),"")
A12: 46035 | B12: Internet fibra | C12: Contas Fixas | D12: 100 | E12: Débito | H12: 46037 | I12: Sim | J12: Itaú | K12: =IF(AND($I12="Não",$H12<>"",$H12<=TODAY()+7),COUNTIFS($H$5:$H$204,"<"&$H12,$I$5:$I$204,"Não",$H$5:$H$204,"<="&TODAY()+7)+COUNTIFS($H$5:$H12,$H12,$I$5:$I12,"Não"),"")
A13: 46038 | B13: Combustível | C13: Transporte | D13: 240 | E13: Crédito | F13: Itaú | H13: 46056 | I13: Sim | J13: Itaú | K13: =IF(AND($I13="Não",$H13<>"",$H13<=TODAY()+7),COUNTIFS($H$5:$H$204,"<"&$H13,$I$5:$I$204,"Não",$H$5:$H$204,"<="&TODAY()+7)+COUNTIFS($H$5:$H13,$H13,$I$5:$I13,"Não"),"")
A14: 46042 | B14: Roupas de trabalho | C14: Vestuário | D14: 180 | E14: Crédito | F14: Itaú | H14: 46056 | I14: Sim | J14: Itaú | K14: =IF(AND($I14="Não",$H14<>"",$H14<=TODAY()+7),COUNTIFS($H$5:$H$204,"<"&$H14,$I$5:$I$204,"Não",$H$5:$H$204,"<="&TODAY()+7)+COUNTIFS($H$5:$H14,$H14,$I$5:$I14,"Não"),"")
A15: 46044 | B15: Restaurantes e delivery | C15: Lazer | D15: 180 | E15: Crédito | F15: Nubank | H15: 46058 | I15: Sim | J15: Nubank | K15: =IF(AND($I15="Não",$H15<>"",$H15<=TODAY()+7),COUNTIFS($H$5:$H$204,"<"&$H15,$I$5:$I$204,"Não",$H$5:$H$204,"<="&TODAY()+7)+COUNTIFS($H$5:$H15,$H15,$I$5:$I15,"Não"),"")
A16: 46054 | B16: Notebook Dell — parcela 1/12 | C16: Outros | D16: 300 | E16: Crédito | F16: Itaú | G16: 12x | H16: 46084 | I16: Sim | J16: Itaú | K16: =IF(AND($I16="Não",$H16<>"",$H16<=TODAY()+7),COUNTIFS($H$5:$H$204,"<"&$H16,$I$5:$I$204,"Não",$H$5:$H$204,"<="&TODAY()+7)+COUNTIFS($H$5:$H16,$H16,$I$5:$I16,"Não"),"")
A17: 46056 | B17: Energia elétrica | C17: Contas Fixas | D17: 182 | E17: Pix | H17: 46061 | I17: Sim | J17: Itaú | K17: =IF(AND($I17="Não",$H17<>"",$H17<=TODAY()+7),COUNTIFS($H$5:$H$204,"<"&$H17,$I$5:$I$204,"Não",$H$5:$H$204,"<="&TODAY()+7)+COUNTIFS($H$5:$H17,$H17,$I$5:$I17,"Não"),"")
A18: 46057 | B18: Academia | C18: Saúde | D18: 90 | E18: Débito | H18: 46058 | I18: Sim | J18: Nubank | K18: =IF(AND($I18="Não",$H18<>"",$H18<=TODAY()+7),COUNTIFS($H$5:$H$204,"<"&$H18,$I$5:$I$204,"Não",$H$5:$H$204,"<="&TODAY()+7)+COUNTIFS($H$5:$H18,$H18,$I$5:$I18,"Não"),"")
A19: 46059 | B19: Streaming (Netflix + Spotify) | C19: Assinaturas | D19: 55 | E19: Crédito | F19: Nubank | H19: 46086 | I19: Sim | J19: Nubank | K19: =IF(AND($I19="Não",$H19<>"",$H19<=TODAY()+7),COUNTIFS($H$5:$H$204,"<"&$H19,$I$5:$I$204,"Não",$H$5:$H$204,"<="&TODAY()+7)+COUNTIFS($H$5:$H19,$H19,$I$5:$I19,"Não"),"")
A20: 46059 | B20: Aporte em investimentos | C20: Investimentos | D20: 500 | E20: Transferência | H20: 46059 | I20: Sim | J20: Itaú | K20: =IF(AND($I20="Não",$H20<>"",$H20<=TODAY()+7),COUNTIFS($H$5:$H$204,"<"&$H20,$I$5:$I$204,"Não",$H$5:$H$204,"<="&TODAY()+7)+COUNTIFS($H$5:$H20,$H20,$I$5:$I20,"Não"),"")
A21: 46061 | B21: Aluguel + condomínio | C21: Moradia | D21: 1500 | E21: Boleto | H21: 46063 | I21: Sim | J21: Itaú | K21: =IF(AND($I21="Não",$H21<>"",$H21<=TODAY()+7),COUNTIFS($H$5:$H$204,"<"&$H21,$I$5:$I$204,"Não",$H$5:$H$204,"<="&TODAY()+7)+COUNTIFS($H$5:$H21,$H21,$I$5:$I21,"Não"),"")
A22: 46062 | B22: IPVA — parcela única | C22: Transporte | D22: 310 | E22: Boleto | H22: 46068 | I22: Sim | J22: Itaú | K22: =IF(AND($I22="Não",$H22<>"",$H22<=TODAY()+7),COUNTIFS($H$5:$H$204,"<"&$H22,$I$5:$I$204,"Não",$H$5:$H$204,"<="&TODAY()+7)+COUNTIFS($H$5:$H22,$H22,$I$5:$I22,"Não"),"")
A23: 46063 | B23: Plano de celular | C23: Contas Fixas | D23: 60 | E23: Débito | H23: 46065 | I23: Sim | J23: Nubank | K23: =IF(AND($I23="Não",$H23<>"",$H23<=TODAY()+7),COUNTIFS($H$5:$H$204,"<"&$H23,$I$5:$I$204,"Não",$H$5:$H$204,"<="&TODAY()+7)+COUNTIFS($H$5:$H23,$H23,$I$5:$I23,"Não"),"")
A24: 46065 | B24: Supermercado do mês | C24: Alimentação | D24: 580 | E24: Crédito | F24: Nubank | H24: 46086 | I24: Sim | J24: Nubank | K24: =IF(AND($I24="Não",$H24<>"",$H24<=TODAY()+7),COUNTIFS($H$5:$H$204,"<"&$H24,$I$5:$I$204,"Não",$H$5:$H$204,"<="&TODAY()+7)+COUNTIFS($H$5:$H24,$H24,$I$5:$I24,"Não"),"")
A25: 46066 | B25: Internet fibra | C25: Contas Fixas | D25: 100 | E25: Débito | H25: 46068 | I25: Sim | J25: Itaú | K25: =IF(AND($I25="Não",$H25<>"",$H25<=TODAY()+7),COUNTIFS($H$5:$H$204,"<"&$H25,$I$5:$I$204,"Não",$H$5:$H$204,"<="&TODAY()+7)+COUNTIFS($H$5:$H25,$H25,$I$5:$I25,"Não"),"")
A26: 46069 | B26: Combustível | C26: Transporte | D26: 220 | E26: Crédito | F26: Itaú | H26: 46084 | I26: Sim | J26: Itaú | K26: =IF(AND($I26="Não",$H26<>"",$H26<=TODAY()+7),COUNTIFS($H$5:$H$204,"<"&$H26,$I$5:$I$204,"Não",$H$5:$H$204,"<="&TODAY()+7)+COUNTIFS($H$5:$H26,$H26,$I$5:$I26,"Não"),"")
A27: 46075 | B27: Restaurantes e delivery | C27: Lazer | D27: 210 | E27: Crédito | F27: Nubank | H27: 46086 | I27: Sim | J27: Nubank | K27: =IF(AND($I27="Não",$H27<>"",$H27<=TODAY()+7),COUNTIFS($H$5:$H$204,"<"&$H27,$I$5:$I$204,"Não",$H$5:$H$204,"<="&TODAY()+7)+COUNTIFS($H$5:$H27,$H27,$I$5:$I27,"Não"),"")
A28: 46082 | B28: Notebook Dell — parcela 2/12 | C28: Outros | D28: 300 | E28: Crédito | F28: Itaú | G28: 12x | H28: 46115 | I28: Sim | J28: Itaú | K28: =IF(AND($I28="Não",$H28<>"",$H28<=TODAY()+7),COUNTIFS($H$5:$H$204,"<"&$H28,$I$5:$I$204,"Não",$H$5:$H$204,"<="&TODAY()+7)+COUNTIFS($H$5:$H28,$H28,$I$5:$I28,"Não"),"")
A29: 46084 | B29: Energia elétrica | C29: Contas Fixas | D29: 160 | E29: Pix | H29: 46089 | I29: Sim | J29: Itaú | K29: =IF(AND($I29="Não",$H29<>"",$H29<=TODAY()+7),COUNTIFS($H$5:$H$204,"<"&$H29,$I$5:$I$204,"Não",$H$5:$H$204,"<="&TODAY()+7)+COUNTIFS($H$5:$H29,$H29,$I$5:$I29,"Não"),"")
A30: 46085 | B30: Academia | C30: Saúde | D30: 90 | E30: Débito | H30: 46086 | I30: Sim | J30: Nubank | K30: =IF(AND($I30="Não",$H30<>"",$H30<=TODAY()+7),COUNTIFS($H$5:$H$204,"<"&$H30,$I$5:$I$204,"Não",$H$5:$H$204,"<="&TODAY()+7)+COUNTIFS($H$5:$H30,$H30,$I$5:$I30,"Não"),"")
A31: 46087 | B31: Streaming (Netflix + Spotify) | C31: Assinaturas | D31: 55 | E31: Crédito | F31: Nubank | H31: 46117 | I31: Sim | J31: Nubank | K31: =IF(AND($I31="Não",$H31<>"",$H31<=TODAY()+7),COUNTIFS($H$5:$H$204,"<"&$H31,$I$5:$I$204,"Não",$H$5:$H$204,"<="&TODAY()+7)+COUNTIFS($H$5:$H31,$H31,$I$5:$I31,"Não"),"")
A32: 46087 | B32: Aporte em investimentos | C32: Investimentos | D32: 500 | E32: Transferência | H32: 46087 | I32: Sim | J32: Itaú | K32: =IF(AND($I32="Não",$H32<>"",$H32<=TODAY()+7),COUNTIFS($H$5:$H$204,"<"&$H32,$I$5:$I$204,"Não",$H$5:$H$204,"<="&TODAY()+7)+COUNTIFS($H$5:$H32,$H32,$I$5:$I32,"Não"),"")
A33: 46089 | B33: Aluguel + condomínio | C33: Moradia | D33: 1500 | E33: Boleto | H33: 46091 | I33: Sim | J33: Itaú | K33: =IF(AND($I33="Não",$H33<>"",$H33<=TODAY()+7),COUNTIFS($H$5:$H$204,"<"&$H33,$I$5:$I$204,"Não",$H$5:$H$204,"<="&TODAY()+7)+COUNTIFS($H$5:$H33,$H33,$I$5:$I33,"Não"),"")
A34: 46091 | B34: Plano de celular | C34: Contas Fixas | D34: 60 | E34: Débito | H34: 46093 | I34: Sim | J34: Nubank | K34: =IF(AND($I34="Não",$H34<>"",$H34<=TODAY()+7),COUNTIFS($H$5:$H$204,"<"&$H34,$I$5:$I$204,"Não",$H$5:$H$204,"<="&TODAY()+7)+COUNTIFS($H$5:$H34,$H34,$I$5:$I34,"Não"),"")
A35: 46093 | B35: Supermercado do mês | C35: Alimentação | D35: 710 | E35: Crédito | F35: Nubank | H35: 46117 | I35: Sim | J35: Nubank | K35: =IF(AND($I35="Não",$H35<>"",$H35<=TODAY()+7),COUNTIFS($H$5:$H$204,"<"&$H35,$I$5:$I$204,"Não",$H$5:$H$204,"<="&TODAY()+7)+COUNTIFS($H$5:$H35,$H35,$I$5:$I35,"Não"),"")
A36: 46094 | B36: Internet fibra | C36: Contas Fixas | D36: 100 | E36: Débito | H36: 46096 | I36: Sim | J36: Itaú | K36: =IF(AND($I36="Não",$H36<>"",$H36<=TODAY()+7),COUNTIFS($H$5:$H$204,"<"&$H36,$I$5:$I$204,"Não",$H$5:$H$204,"<="&TODAY()+7)+COUNTIFS($H$5:$H36,$H36,$I$5:$I36,"Não"),"")
A37: 46095 | B37: Consulta médica | C37: Saúde | D37: 150 | E37: Pix | H37: 46095 | I37: Sim | J37: Nubank | K37: =IF(AND($I37="Não",$H37<>"",$H37<=TODAY()+7),COUNTIFS($H$5:$H$204,"<"&$H37,$I$5:$I$204,"Não",$H$5:$H$204,"<="&TODAY()+7)+COUNTIFS($H$5:$H37,$H37,$I$5:$I37,"Não"),"")
A38: 46097 | B38: Combustível | C38: Transporte | D38: 260 | E38: Crédito | F38: Itaú | H38: 46115 | I38: Sim | J38: Itaú | K38: =IF(AND($I38="Não",$H38<>"",$H38<=TODAY()+7),COUNTIFS($H$5:$H$204,"<"&$H38,$I$5:$I$204,"Não",$H$5:$H$204,"<="&TODAY()+7)+COUNTIFS($H$5:$H38,$H38,$I$5:$I38,"Não"),"")
A39: 46103 | B39: Restaurantes e delivery | C39: Lazer | D39: 150 | E39: Crédito | F39: Nubank | H39: 46117 | I39: Sim | J39: Nubank | K39: =IF(AND($I39="Não",$H39<>"",$H39<=TODAY()+7),COUNTIFS($H$5:$H$204,"<"&$H39,$I$5:$I$204,"Não",$H$5:$H$204,"<="&TODAY()+7)+COUNTIFS($H$5:$H39,$H39,$I$5:$I39,"Não"),"")
A40: 46113 | B40: Notebook Dell — parcela 3/12 | C40: Outros | D40: 300 | E40: Crédito | F40: Itaú | G40: 12x | H40: 46145 | I40: Sim | J40: Itaú | K40: =IF(AND($I40="Não",$H40<>"",$H40<=TODAY()+7),COUNTIFS($H$5:$H$204,"<"&$H40,$I$5:$I$204,"Não",$H$5:$H$204,"<="&TODAY()+7)+COUNTIFS($H$5:$H40,$H40,$I$5:$I40,"Não"),"")
A41: 46114 | B41: Curso online de inglês | C41: Educação | D41: 120 | E41: Crédito | F41: Nubank | H41: 46147 | I41: Sim | J41: Nubank | K41: =IF(AND($I41="Não",$H41<>"",$H41<=TODAY()+7),COUNTIFS($H$5:$H$204,"<"&$H41,$I$5:$I$204,"Não",$H$5:$H$204,"<="&TODAY()+7)+COUNTIFS($H$5:$H41,$H41,$I$5:$I41,"Não"),"")
...

Sheet 🏦 Contas
B1: 📊 Início | C1: 💰 Receitas | D1: 💸 Despesas | E1: 🏦 Contas | F1: 💳 Cartões | G1: 🎯 Metas | H1: 📅 Orçamento | I1: 📈 Relatórios | J1: 🔔 Alertas | K1: ⚙️ Config
B3: 🏦 Contas Bancárias
B4: Entradas, saídas e transferências entram automaticamente no saldo.
A6: Banco / Conta | B6: Saldo Inicial | C6: Entradas | D6: Saídas | E6: Transf. Recebidas | F6: Transf. Enviadas | G6: Saldo Atual
A7: Itaú | B7: 2500 | C7: =IF($A7="","",SUMIFS('💰 Receitas'!$D:$D,'💰 Receitas'!$F:$F,$A7,'💰 Receitas'!$G:$G,"Recebido")) | D7: =IF($A7="","",SUMIFS('💸 Despesas'!$D:$D,'💸 Despesas'!$J:$J,$A7,'💸 Despesas'!$I:$I,"Sim")) | E7: =IF($A7="","",SUMIFS($D$22:$D$36,$C$22:$C$36,$A7)) | F7: =IF($A7="","",SUMIFS($D$22:$D$36,$B$22:$B$36,$A7)) | G7: =IF($A7="","",$B7+$C7-$D7+$E7-$F7)
A8: Nubank | B8: 1200 | C8: =IF($A8="","",SUMIFS('💰 Receitas'!$D:$D,'💰 Receitas'!$F:$F,$A8,'💰 Receitas'!$G:$G,"Recebido")) | D8: =IF($A8="","",SUMIFS('💸 Despesas'!$D:$D,'💸 Despesas'!$J:$J,$A8,'💸 Despesas'!$I:$I,"Sim")) | E8: =IF($A8="","",SUMIFS($D$22:$D$36,$C$22:$C$36,$A8)) | F8: =IF($A8="","",SUMIFS($D$22:$D$36,$B$22:$B$36,$A8)) | G8: =IF($A8="","",$B8+$C8-$D8+$E8-$F8)
A9: Caixa | B9: 800 | C9: =IF($A9="","",SUMIFS('💰 Receitas'!$D:$D,'💰 Receitas'!$F:$F,$A9,'💰 Receitas'!$G:$G,"Recebido")) | D9: =IF($A9="","",SUMIFS('💸 Despesas'!$D:$D,'💸 Despesas'!$J:$J,$A9,'💸 Despesas'!$I:$I,"Sim")) | E9: =IF($A9="","",SUMIFS($D$22:$D$36,$C$22:$C$36,$A9)) | F9: =IF($A9="","",SUMIFS($D$22:$D$36,$B$22:$B$36,$A9)) | G9: =IF($A9="","",$B9+$C9-$D9+$E9-$F9)
A10: Inter | B10: 300 | C10: =IF($A10="","",SUMIFS('💰 Receitas'!$D:$D,'💰 Receitas'!$F:$F,$A10,'💰 Receitas'!$G:$G,"Recebido")) | D10: =IF($A10="","",SUMIFS('💸 Despesas'!$D:$D,'💸 Despesas'!$J:$J,$A10,'💸 Despesas'!$I:$I,"Sim")) | E10: =IF($A10="","",SUMIFS($D$22:$D$36,$C$22:$C$36,$A10)) | F10: =IF($A10="","",SUMIFS($D$22:$D$36,$B$22:$B$36,$A10)) | G10: =IF($A10="","",$B10+$C10-$D10+$E10-$F10)
A11: Carteira | B11: 150 | C11: =IF($A11="","",SUMIFS('💰 Receitas'!$D:$D,'💰 Receitas'!$F:$F,$A11,'💰 Receitas'!$G:$G,"Recebido")) | D11: =IF($A11="","",SUMIFS('💸 Despesas'!$D:$D,'💸 Despesas'!$J:$J,$A11,'💸 Despesas'!$I:$I,"Sim")) | E11: =IF($A11="","",SUMIFS($D$22:$D$36,$C$22:$C$36,$A11)) | F11: =IF($A11="","",SUMIFS($D$22:$D$36,$B$22:$B$36,$A11)) | G11: =IF($A11="","",$B11+$C11-$D11+$E11-$F11)
C12: =IF($A12="","",SUMIFS('💰 Receitas'!$D:$D,'💰 Receitas'!$F:$F,$A12,'💰 Receitas'!$G:$G,"Recebido")) | D12: =IF($A12="","",SUMIFS('💸 Despesas'!$D:$D,'💸 Despesas'!$J:$J,$A12,'💸 Despesas'!$I:$I,"Sim")) | E12: =IF($A12="","",SUMIFS($D$22:$D$36,$C$22:$C$36,$A12)) | F12: =IF($A12="","",SUMIFS($D$22:$D$36,$B$22:$B$36,$A12)) | G12: =IF($A12="","",$B12+$C12-$D12+$E12-$F12)
C13: =IF($A13="","",SUMIFS('💰 Receitas'!$D:$D,'💰 Receitas'!$F:$F,$A13,'💰 Receitas'!$G:$G,"Recebido")) | D13: =IF($A13="","",SUMIFS('💸 Despesas'!$D:$D,'💸 Despesas'!$J:$J,$A13,'💸 Despesas'!$I:$I,"Sim")) | E13: =IF($A13="","",SUMIFS($D$22:$D$36,$C$22:$C$36,$A13)) | F13: =IF($A13="","",SUMIFS($D$22:$D$36,$B$22:$B$36,$A13)) | G13: =IF($A13="","",$B13+$C13-$D13+$E13-$F13)
C14: =IF($A14="","",SUMIFS('💰 Receitas'!$D:$D,'💰 Receitas'!$F:$F,$A14,'💰 Receitas'!$G:$G,"Recebido")) | D14: =IF($A14="","",SUMIFS('💸 Despesas'!$D:$D,'💸 Despesas'!$J:$J,$A14,'💸 Despesas'!$I:$I,"Sim")) | E14: =IF($A14="","",SUMIFS($D$22:$D$36,$C$22:$C$36,$A14)) | F14: =IF($A14="","",SUMIFS($D$22:$D$36,$B$22:$B$36,$A14)) | G14: =IF($A14="","",$B14+$C14-$D14+$E14-$F14)
A15: TOTAL | B15: =SUM(B7:B14) | C15: =SUM(C7:C14) | D15: =SUM(D7:D14) | E15: =SUM(E7:E14) | F15: =SUM(F7:F14) | G15: =SUM(G7:G14)
A19: 🔁 Transferências entre contas
A21: Data | B21: De (conta) | C21: Para (conta) | D21: Valor | E21: Observação
A22: 46152 | B22: Nubank | C22: Carteira | D22: 200 | E22: Dinheiro p/ semana
A23: 46188 | B23: Itaú | C23: Nubank | D23: 400 | E23: Cobrir fatura
A24: 46204 | B24: Itaú | C24: Inter | D24: 300 | E24: Investimento

Sheet 💳 Cartões
B1: 📊 Início | C1: 💰 Receitas | D1: 💸 Despesas | E1: 🏦 Contas | F1: 💳 Cartões | G1: 🎯 Metas | H1: 📅 Orçamento | I1: 📈 Relatórios | J1: 🔔 Alertas | K1: ⚙️ Config
B3: 💳 Controle de Cartões
B4: A fatura soma as compras no crédito ainda não pagas na aba 💸 Despesas.
A6: Cartão | B6: Limite | C6: Fatura Atual | D6: Limite Disponível | E6: % Utilizado | F6: Uso do limite | G6: Dia Fechamento | H6: Dia Vencimento | I6: Melhor Dia de Compra
A7: Nubank | B7: 4500 | C7: =IF($A7="","",SUMIFS('💸 Despesas'!$D:$D,'💸 Despesas'!$F:$F,$A7,'💸 Despesas'!$E:$E,"Crédito",'💸 Despesas'!$I:$I,"Não")) | D7: =IF($A7="","",$B7-$C7) | E7: =IF(OR($A7="",$B7=0),"",$C7/$B7) | F7: =IF($E7="","",REPT("█",MIN(10,ROUND($E7*10,0)))&REPT("░",10-MIN(10,ROUND($E7*10,0)))) | G7: 28 | H7: 5 | I7: =IF($G7="","",IF($G7>=28,1,$G7+1))
A8: Itaú | B8: 6000 | C8: =IF($A8="","",SUMIFS('💸 Despesas'!$D:$D,'💸 Despesas'!$F:$F,$A8,'💸 Despesas'!$E:$E,"Crédito",'💸 Despesas'!$I:$I,"Não")) | D8: =IF($A8="","",$B8-$C8) | E8: =IF(OR($A8="",$B8=0),"",$C8/$B8) | F8: =IF($E8="","",REPT("█",MIN(10,ROUND($E8*10,0)))&REPT("░",10-MIN(10,ROUND($E8*10,0)))) | G8: 25 | H8: 3 | I8: =IF($G8="","",IF($G8>=28,1,$G8+1))
A9: Inter | B9: 2000 | C9: =IF($A9="","",SUMIFS('💸 Despesas'!$D:$D,'💸 Despesas'!$F:$F,$A9,'💸 Despesas'!$E:$E,"Crédito",'💸 Despesas'!$I:$I,"Não")) | D9: =IF($A9="","",$B9-$C9) | E9: =IF(OR($A9="",$B9=0),"",$C9/$B9) | F9: =IF($E9="","",REPT("█",MIN(10,ROUND($E9*10,0)))&REPT("░",10-MIN(10,ROUND($E9*10,0)))) | G9: 20 | H9: 27 | I9: =IF($G9="","",IF($G9>=28,1,$G9+1))
C10: =IF($A10="","",SUMIFS('💸 Despesas'!$D:$D,'💸 Despesas'!$F:$F,$A10,'💸 Despesas'!$E:$E,"Crédito",'💸 Despesas'!$I:$I,"Não")) | D10: =IF($A10="","",$B10-$C10) | E10: =IF(OR($A10="",$B10=0),"",$C10/$B10) | F10: =IF($E10="","",REPT("█",MIN(10,ROUND($E10*10,0)))&REPT("░",10-MIN(10,ROUND($E10*10,0)))) | I10: =IF($G10="","",IF($G10>=28,1,$G10+1))
C11: =IF($A11="","",SUMIFS('💸 Despesas'!$D:$D,'💸 Despesas'!$F:$F,$A11,'💸 Despesas'!$E:$E,"Crédito",'💸 Despesas'!$I:$I,"Não")) | D11: =IF($A11="","",$B11-$C11) | E11: =IF(OR($A11="",$B11=0),"",$C11/$B11) | F11: =IF($E11="","",REPT("█",MIN(10,ROUND($E11*10,0)))&REPT("░",10-MIN(10,ROUND($E11*10,0)))) | I11: =IF($G11="","",IF($G11>=28,1,$G11+1))
C12: =IF($A12="","",SUMIFS('💸 Despesas'!$D:$D,'💸 Despesas'!$F:$F,$A12,'💸 Despesas'!$E:$E,"Crédito",'💸 Despesas'!$I:$I,"Não")) | D12: =IF($A12="","",$B12-$C12) | E12: =IF(OR($A12="",$B12=0),"",$C12/$B12) | F12: =IF($E12="","",REPT("█",MIN(10,ROUND($E12*10,0)))&REPT("░",10-MIN(10,ROUND($E12*10,0)))) | I12: =IF($G12="","",IF($G12>=28,1,$G12+1))
A15: 📆 Parcelamentos em andamento
A17: Descrição | B17: Cartão | C17: Valor Total | D17: Nº Parcelas | E17: Valor da Parcela | F17: Parcelas Pagas | G17: Falta Pagar | H17: Situação
A18: Notebook Dell | B18: Itaú | C18: 3600 | D18: 12 | E18: =IF(OR($C18="",$D18=""),"",$C18/$D18) | F18: 6 | G18: =IF($E18="","",$C18-$E18*$F18) | H18: =IF($E18="","",IF($F18>=$D18,"✅ Quitado","⏳ "&$F18&"/"&$D18&" pagas"))
A19: Smartphone | B19: Nubank | C19: 2400 | D19: 10 | E19: =IF(OR($C19="",$D19=""),"",$C19/$D19) | F19: 3 | G19: =IF($E19="","",$C19-$E19*$F19) | H19: =IF($E19="","",IF($F19>=$D19,"✅ Quitado","⏳ "&$F19&"/"&$D19&" pagas"))
E20: =IF(OR($C20="",$D20=""),"",$C20/$D20) | G20: =IF($E20="","",$C20-$E20*$F20) | H20: =IF($E20="","",IF($F20>=$D20,"✅ Quitado","⏳ "&$F20&"/"&$D20&" pagas"))
E21: =IF(OR($C21="",$D21=""),"",$C21/$D21) | G21: =IF($E21="","",$C21-$E21*$F21) | H21: =IF($E21="","",IF($F21>=$D21,"✅ Quitado","⏳ "&$F21&"/"&$D21&" pagas"))
E22: =IF(OR($C22="",$D22=""),"",$C22/$D22) | G22: =IF($E22="","",$C22-$E22*$F22) | H22: =IF($E22="","",IF($F22>=$D22,"✅ Quitado","⏳ "&$F22&"/"&$D22&" pagas"))
E23: =IF(OR($C23="",$D23=""),"",$C23/$D23) | G23: =IF($E23="","",$C23-$E23*$F23) | H23: =IF($E23="","",IF($F23>=$D23,"✅ Quitado","⏳ "&$F23&"/"&$D23&" pagas"))
E24: =IF(OR($C24="",$D24=""),"",$C24/$D24) | G24: =IF($E24="","",$C24-$E24*$F24) | H24: =IF($E24="","",IF($F24>=$D24,"✅ Quitado","⏳ "&$F24&"/"&$D24&" pagas"))
E25: =IF(OR($C25="",$D25=""),"",$C25/$D25) | G25: =IF($E25="","",$C25-$E25*$F25) | H25: =IF($E25="","",IF($F25>=$D25,"✅ Quitado","⏳ "&$F25&"/"&$D25&" pagas"))
E26: =IF(OR($C26="",$D26=""),"",$C26/$D26) | G26: =IF($E26="","",$C26-$E26*$F26) | H26: =IF($E26="","",IF($F26>=$D26,"✅ Quitado","⏳ "&$F26&"/"&$D26&" pagas"))
E27: =IF(OR($C27="",$D27=""),"",$C27/$D27) | G27: =IF($E27="","",$C27-$E27*$F27) | H27: =IF($E27="","",IF($F27>=$D27,"✅ Quitado","⏳ "&$F27&"/"&$D27&" pagas"))

Sheet 🎯 Metas
B1: 📊 Início | C1: 💰 Receitas | D1: 💸 Despesas | E1: 🏦 Contas | F1: 💳 Cartões | G1: 🎯 Metas | H1: 📅 Orçamento | I1: 📈 Relatórios | J1: 🔔 Alertas | K1: ⚙️ Config
B3: 🎯 Metas Financeiras
B4: Informe a meta, o quanto já guardou e o aporte mensal — o resto é automático.
A6: Meta | B6: Valor Desejado | C6: Valor Guardado | D6: Valor Restante | E6: Progresso | F6: % | G6: Aporte Mensal | H6: Meses Restantes | I6: Previsão de Conclusão | J6: Status
A7: Reserva de emergência | B7: 15000 | C7: 8200 | D7: =IF($B7="","",MAX($B7-$C7,0)) | E7: =IF($B7="","",REPT("█",MIN(10,ROUND($F7*10,0)))&REPT("░",10-MIN(10,ROUND($F7*10,0)))) | F7: =IF($B7="","",MIN($C7/$B7,1)) | G7: 600 | H7: =IF(OR($B7="",$C7>=$B7),"",IF($G7>0,ROUNDUP(($B7-$C7)/$G7,0),"—")) | I7: =IF(OR($B7="",$C7>=$B7,$G7<=0),"",EDATE(TODAY(),ROUNDUP(($B7-$C7)/$G7,0))) | J7: =IF($B7="","",IF($C7>=$B7,"🎉 Atingida!",IF($F7>=0.7,"🔥 Quase lá",IF($F7>=0.3,"💪 Em progresso","🚀 Começando"))))
A8: Viagem de férias | B8: 6000 | C8: 2100 | D8: =IF($B8="","",MAX($B8-$C8,0)) | E8: =IF($B8="","",REPT("█",MIN(10,ROUND($F8*10,0)))&REPT("░",10-MIN(10,ROUND($F8*10,0)))) | F8: =IF($B8="","",MIN($C8/$B8,1)) | G8: 400 | H8: =IF(OR($B8="",$C8>=$B8),"",IF($G8>0,ROUNDUP(($B8-$C8)/$G8,0),"—")) | I8: =IF(OR($B8="",$C8>=$B8,$G8<=0),"",EDATE(TODAY(),ROUNDUP(($B8-$C8)/$G8,0))) | J8: =IF($B8="","",IF($C8>=$B8,"🎉 Atingida!",IF($F8>=0.7,"🔥 Quase lá",IF($F8>=0.3,"💪 Em progresso","🚀 Começando"))))
A9: Notebook novo | B9: 4500 | C9: 4500 | D9: =IF($B9="","",MAX($B9-$C9,0)) | E9: =IF($B9="","",REPT("█",MIN(10,ROUND($F9*10,0)))&REPT("░",10-MIN(10,ROUND($F9*10,0)))) | F9: =IF($B9="","",MIN($C9/$B9,1)) | G9: 0 | H9: =IF(OR($B9="",$C9>=$B9),"",IF($G9>0,ROUNDUP(($B9-$C9)/$G9,0),"—")) | I9: =IF(OR($B9="",$C9>=$B9,$G9<=0),"",EDATE(TODAY(),ROUNDUP(($B9-$C9)/$G9,0))) | J9: =IF($B9="","",IF($C9>=$B9,"🎉 Atingida!",IF($F9>=0.7,"🔥 Quase lá",IF($F9>=0.3,"💪 Em progresso","🚀 Começando"))))
A10: Entrada do apartamento | B10: 40000 | C10: 5500 | D10: =IF($B10="","",MAX($B10-$C10,0)) | E10: =IF($B10="","",REPT("█",MIN(10,ROUND($F10*10,0)))&REPT("░",10-MIN(10,ROUND($F10*10,0)))) | F10: =IF($B10="","",MIN($C10/$B10,1)) | G10: 800 | H10: =IF(OR($B10="",$C10>=$B10),"",IF($G10>0,ROUNDUP(($B10-$C10)/$G10,0),"—")) | I10: =IF(OR($B10="",$C10>=$B10,$G10<=0),"",EDATE(TODAY(),ROUNDUP(($B10-$C10)/$G10,0))) | J10: =IF($B10="","",IF($C10>=$B10,"🎉 Atingida!",IF($F10>=0.7,"🔥 Quase lá",IF($F10>=0.3,"💪 Em progresso","🚀 Começando"))))
D11: =IF($B11="","",MAX($B11-$C11,0)) | E11: =IF($B11="","",REPT("█",MIN(10,ROUND($F11*10,0)))&REPT("░",10-MIN(10,ROUND($F11*10,0)))) | F11: =IF($B11="","",MIN($C11/$B11,1)) | H11: =IF(OR($B11="",$C11>=$B11),"",IF($G11>0,ROUNDUP(($B11-$C11)/$G11,0),"—")) | I11: =IF(OR($B11="",$C11>=$B11,$G11<=0),"",EDATE(TODAY(),ROUNDUP(($B11-$C11)/$G11,0))) | J11: =IF($B11="","",IF($C11>=$B11,"🎉 Atingida!",IF($F11>=0.7,"🔥 Quase lá",IF($F11>=0.3,"💪 Em progresso","🚀 Começando"))))
D12: =IF($B12="","",MAX($B12-$C12,0)) | E12: =IF($B12="","",REPT("█",MIN(10,ROUND($F12*10,0)))&REPT("░",10-MIN(10,ROUND($F12*10,0)))) | F12: =IF($B12="","",MIN($C12/$B12,1)) | H12: =IF(OR($B12="",$C12>=$B12),"",IF($G12>0,ROUNDUP(($B12-$C12)/$G12,0),"—")) | I12: =IF(OR($B12="",$C12>=$B12,$G12<=0),"",EDATE(TODAY(),ROUNDUP(($B12-$C12)/$G12,0))) | J12: =IF($B12="","",IF($C12>=$B12,"🎉 Atingida!",IF($F12>=0.7,"🔥 Quase lá",IF($F12>=0.3,"💪 Em progresso","🚀 Começando"))))
D13: =IF($B13="","",MAX($B13-$C13,0)) | E13: =IF($B13="","",REPT("█",MIN(10,ROUND($F13*10,0)))&REPT("░",10-MIN(10,ROUND($F13*10,0)))) | F13: =IF($B13="","",MIN($C13/$B13,1)) | H13: =IF(OR($B13="",$C13>=$B13),"",IF($G13>0,ROUNDUP(($B13-$C13)/$G13,0),"—")) | I13: =IF(OR($B13="",$C13>=$B13,$G13<=0),"",EDATE(TODAY(),ROUNDUP(($B13-$C13)/$G13,0))) | J13: =IF($B13="","",IF($C13>=$B13,"🎉 Atingida!",IF($F13>=0.7,"🔥 Quase lá",IF($F13>=0.3,"💪 Em progresso","🚀 Começando"))))
D14: =IF($B14="","",MAX($B14-$C14,0)) | E14: =IF($B14="","",REPT("█",MIN(10,ROUND($F14*10,0)))&REPT("░",10-MIN(10,ROUND($F14*10,0)))) | F14: =IF($B14="","",MIN($C14/$B14,1)) | H14: =IF(OR($B14="",$C14>=$B14),"",IF($G14>0,ROUNDUP(($B14-$C14)/$G14,0),"—")) | I14: =IF(OR($B14="",$C14>=$B14,$G14<=0),"",EDATE(TODAY(),ROUNDUP(($B14-$C14)/$G14,0))) | J14: =IF($B14="","",IF($C14>=$B14,"🎉 Atingida!",IF($F14>=0.7,"🔥 Quase lá",IF($F14>=0.3,"💪 Em progresso","🚀 Começando"))))

Sheet 📅 Planejamento
B1: 📊 Início | C1: 💰 Receitas | D1: 💸 Despesas | E1: 🏦 Contas | F1: 💳 Cartões | G1: 🎯 Metas | H1: 📅 Orçamento | I1: 📈 Relatórios | J1: 🔔 Alertas | K1: ⚙️ Config
B3: 📅 Planejamento Mensal
B4: ="Orçamento de "&INDEX('⚙️ Config'!$H$7:$H$18,'📊 Dashboard'!$J$3)&" de "&'📊 Dashboard'!$L$3&" — mude o mês no 📊 Dashboard"
A6: Categoria | B6: Orçamento | C6: Valor Gasto | D6: Diferença | E6: % Usado | F6: Consumo | G6: Situação
A7: Moradia | B7: 1900 | C7: =SUMIFS('💸 Despesas'!$D:$D,'💸 Despesas'!$C:$C,$A7,'💸 Despesas'!$A:$A,">="&DATE('📊 Dashboard'!$L$3,'📊 Dashboard'!$J$3,1),'💸 Despesas'!$A:$A,"<="&EOMONTH(DATE('📊 Dashboard'!$L$3,'📊 Dashboard'!$J$3,1),0)) | D7: =$B7-$C7 | E7: =IFERROR($C7/$B7,0) | F7: =REPT("█",MIN(10,ROUND($E7*10,0)))&REPT("░",10-MIN(10,ROUND($E7*10,0))) | G7: =IF($C7>$B7,"🔴 Estourou",IF($E7>=0.8,"🟡 Atenção","🟢 Dentro"))
A8: Alimentação | B8: 900 | C8: =SUMIFS('💸 Despesas'!$D:$D,'💸 Despesas'!$C:$C,$A8,'💸 Despesas'!$A:$A,">="&DATE('📊 Dashboard'!$L$3,'📊 Dashboard'!$J$3,1),'💸 Despesas'!$A:$A,"<="&EOMONTH(DATE('📊 Dashboard'!$L$3,'📊 Dashboard'!$J$3,1),0)) | D8: =$B8-$C8 | E8: =IFERROR($C8/$B8,0) | F8: =REPT("█",MIN(10,ROUND($E8*10,0)))&REPT("░",10-MIN(10,ROUND($E8*10,0))) | G8: =IF($C8>$B8,"🔴 Estourou",IF($E8>=0.8,"🟡 Atenção","🟢 Dentro"))
A9: Transporte | B9: 350 | C9: =SUMIFS('💸 Despesas'!$D:$D,'💸 Despesas'!$C:$C,$A9,'💸 Despesas'!$A:$A,">="&DATE('📊 Dashboard'!$L$3,'📊 Dashboard'!$J$3,1),'💸 Despesas'!$A:$A,"<="&EOMONTH(DATE('📊 Dashboard'!$L$3,'📊 Dashboard'!$J$3,1),0)) | D9: =$B9-$C9 | E9: =IFERROR($C9/$B9,0) | F9: =REPT("█",MIN(10,ROUND($E9*10,0)))&REPT("░",10-MIN(10,ROUND($E9*10,0))) | G9: =IF($C9>$B9,"🔴 Estourou",IF($E9>=0.8,"🟡 Atenção","🟢 Dentro"))
A10: Saúde | B10: 250 | C10: =SUMIFS('💸 Despesas'!$D:$D,'💸 Despesas'!$C:$C,$A10,'💸 Despesas'!$A:$A,">="&DATE('📊 Dashboard'!$L$3,'📊 Dashboard'!$J$3,1),'💸 Despesas'!$A:$A,"<="&EOMONTH(DATE('📊 Dashboard'!$L$3,'📊 Dashboard'!$J$3,1),0)) | D10: =$B10-$C10 | E10: =IFERROR($C10/$B10,0) | F10: =REPT("█",MIN(10,ROUND($E10*10,0)))&REPT("░",10-MIN(10,ROUND($E10*10,0))) | G10: =IF($C10>$B10,"🔴 Estourou",IF($E10>=0.8,"🟡 Atenção","🟢 Dentro"))
A11: Educação | B11: 150 | C11: =SUMIFS('💸 Despesas'!$D:$D,'💸 Despesas'!$C:$C,$A11,'💸 Despesas'!$A:$A,">="&DATE('📊 Dashboard'!$L$3,'📊 Dashboard'!$J$3,1),'💸 Despesas'!$A:$A,"<="&EOMONTH(DATE('📊 Dashboard'!$L$3,'📊 Dashboard'!$J$3,1),0)) | D11: =$B11-$C11 | E11: =IFERROR($C11/$B11,0) | F11: =REPT("█",MIN(10,ROUND($E11*10,0)))&REPT("░",10-MIN(10,ROUND($E11*10,0))) | G11: =IF($C11>$B11,"🔴 Estourou",IF($E11>=0.8,"🟡 Atenção","🟢 Dentro"))
A12: Lazer | B12: 250 | C12: =SUMIFS('💸 Despesas'!$D:$D,'💸 Despesas'!$C:$C,$A12,'💸 Despesas'!$A:$A,">="&DATE('📊 Dashboard'!$L$3,'📊 Dashboard'!$J$3,1),'💸 Despesas'!$A:$A,"<="&EOMONTH(DATE('📊 Dashboard'!$L$3,'📊 Dashboard'!$J$3,1),0)) | D12: =$B12-$C12 | E12: =IFERROR($C12/$B12,0) | F12: =REPT("█",MIN(10,ROUND($E12*10,0)))&REPT("░",10-MIN(10,ROUND($E12*10,0))) | G12: =IF($C12>$B12,"🔴 Estourou",IF($E12>=0.8,"🟡 Atenção","🟢 Dentro"))
A13: Vestuário | B13: 150 | C13: =SUMIFS('💸 Despesas'!$D:$D,'💸 Despesas'!$C:$C,$A13,'💸 Despesas'!$A:$A,">="&DATE('📊 Dashboard'!$L$3,'📊 Dashboard'!$J$3,1),'💸 Despesas'!$A:$A,"<="&EOMONTH(DATE('📊 Dashboard'!$L$3,'📊 Dashboard'!$J$3,1),0)) | D13: =$B13-$C13 | E13: =IFERROR($C13/$B13,0) | F13: =REPT("█",MIN(10,ROUND($E13*10,0)))&REPT("░",10-MIN(10,ROUND($E13*10,0))) | G13: =IF($C13>$B13,"🔴 Estourou",IF($E13>=0.8,"🟡 Atenção","🟢 Dentro"))
A14: Assinaturas | B14: 120 | C14: =SUMIFS('💸 Despesas'!$D:$D,'💸 Despesas'!$C:$C,$A14,'💸 Despesas'!$A:$A,">="&DATE('📊 Dashboard'!$L$3,'📊 Dashboard'!$J$3,1),'💸 Despesas'!$A:$A,"<="&EOMONTH(DATE('📊 Dashboard'!$L$3,'📊 Dashboard'!$J$3,1),0)) | D14: =$B14-$C14 | E14: =IFERROR($C14/$B14,0) | F14: =REPT("█",MIN(10,ROUND($E14*10,0)))&REPT("░",10-MIN(10,ROUND($E14*10,0))) | G14: =IF($C14>$B14,"🔴 Estourou",IF($E14>=0.8,"🟡 Atenção","🟢 Dentro"))
A15: Contas Fixas | B15: 400 | C15: =SUMIFS('💸 Despesas'!$D:$D,'💸 Despesas'!$C:$C,$A15,'💸 Despesas'!$A:$A,">="&DATE('📊 Dashboard'!$L$3,'📊 Dashboard'!$J$3,1),'💸 Despesas'!$A:$A,"<="&EOMONTH(DATE('📊 Dashboard'!$L$3,'📊 Dashboard'!$J$3,1),0)) | D15: =$B15-$C15 | E15: =IFERROR($C15/$B15,0) | F15: =REPT("█",MIN(10,ROUND($E15*10,0)))&REPT("░",10-MIN(10,ROUND($E15*10,0))) | G15: =IF($C15>$B15,"🔴 Estourou",IF($E15>=0.8,"🟡 Atenção","🟢 Dentro"))
A16: Investimentos | B16: 600 | C16: =SUMIFS('💸 Despesas'!$D:$D,'💸 Despesas'!$C:$C,$A16,'💸 Despesas'!$A:$A,">="&DATE('📊 Dashboard'!$L$3,'📊 Dashboard'!$J$3,1),'💸 Despesas'!$A:$A,"<="&EOMONTH(DATE('📊 Dashboard'!$L$3,'📊 Dashboard'!$J$3,1),0)) | D16: =$B16-$C16 | E16: =IFERROR($C16/$B16,0) | F16: =REPT("█",MIN(10,ROUND($E16*10,0)))&REPT("░",10-MIN(10,ROUND($E16*10,0))) | G16: =IF($C16>$B16,"🔴 Estourou",IF($E16>=0.8,"🟡 Atenção","🟢 Dentro"))
A17: Outros | B17: 700 | C17: =SUMIFS('💸 Despesas'!$D:$D,'💸 Despesas'!$C:$C,$A17,'💸 Despesas'!$A:$A,">="&DATE('📊 Dashboard'!$L$3,'📊 Dashboard'!$J$3,1),'💸 Despesas'!$A:$A,"<="&EOMONTH(DATE('📊 Dashboard'!$L$3,'📊 Dashboard'!$J$3,1),0)) | D17: =$B17-$C17 | E17: =IFERROR($C17/$B17,0) | F17: =REPT("█",MIN(10,ROUND($E17*10,0)))&REPT("░",10-MIN(10,ROUND($E17*10,0))) | G17: =IF($C17>$B17,"🔴 Estourou",IF($E17>=0.8,"🟡 Atenção","🟢 Dentro"))
A18: TOTAL | B18: =SUM(B7:B17) | C18: =SUM(C7:C17) | D18: =SUM(D7:D17) | E18: =IFERROR($C18/$B18,0)

Sheet 📈 Relatórios
B1: 📊 Início | C1: 💰 Receitas | D1: 💸 Despesas | E1: 🏦 Contas | F1: 💳 Cartões | G1: 🎯 Metas | H1: 📅 Orçamento | I1: 📈 Relatórios | J1: 🔔 Alertas | K1: ⚙️ Config
B3: 📈 Relatórios
B4: ="Ano de referência: "&'📊 Dashboard'!$L$3&" (definido no 📊 Dashboard)"
A6: Resumo mensal | G6: Gastos por categoria (mês selecionado)
A7: Mês | B7: Receitas | C7: Despesas | D7: Saldo | E7: Patrimônio | G7: Categoria | H7: Valor | I7: %
A8: Jan | B8: =SUMIFS('💰 Receitas'!$D:$D,'💰 Receitas'!$A:$A,">="&DATE('📊 Dashboard'!$L$3,1,1),'💰 Receitas'!$A:$A,"<="&EOMONTH(DATE('📊 Dashboard'!$L$3,1,1),0)) | C8: =SUMIFS('💸 Despesas'!$D:$D,'💸 Despesas'!$A:$A,">="&DATE('📊 Dashboard'!$L$3,1,1),'💸 Despesas'!$A:$A,"<="&EOMONTH(DATE('📊 Dashboard'!$L$3,1,1),0)) | D8: =$B8-$C8 | E8: ='🏦 Contas'!$B$15+$D8 | G8: Moradia | H8: =SUMIFS('💸 Despesas'!$D:$D,'💸 Despesas'!$C:$C,$G8,'💸 Despesas'!$A:$A,">="&DATE('📊 Dashboard'!$L$3,'📊 Dashboard'!$J$3,1),'💸 Despesas'!$A:$A,"<="&EOMONTH(DATE('📊 Dashboard'!$L$3,'📊 Dashboard'!$J$3,1),0)) | I8: =IFERROR($H8/SUM($H$8:$H$18),0)
A9: Fev | B9: =SUMIFS('💰 Receitas'!$D:$D,'💰 Receitas'!$A:$A,">="&DATE('📊 Dashboard'!$L$3,2,1),'💰 Receitas'!$A:$A,"<="&EOMONTH(DATE('📊 Dashboard'!$L$3,2,1),0)) | C9: =SUMIFS('💸 Despesas'!$D:$D,'💸 Despesas'!$A:$A,">="&DATE('📊 Dashboard'!$L$3,2,1),'💸 Despesas'!$A:$A,"<="&EOMONTH(DATE('📊 Dashboard'!$L$3,2,1),0)) | D9: =$B9-$C9 | E9: =$E8+$D9 | G9: Alimentação | H9: =SUMIFS('💸 Despesas'!$D:$D,'💸 Despesas'!$C:$C,$G9,'💸 Despesas'!$A:$A,">="&DATE('📊 Dashboard'!$L$3,'📊 Dashboard'!$J$3,1),'💸 Despesas'!$A:$A,"<="&EOMONTH(DATE('📊 Dashboard'!$L$3,'📊 Dashboard'!$J$3,1),0)) | I9: =IFERROR($H9/SUM($H$8:$H$18),0)
A10: Mar | B10: =SUMIFS('💰 Receitas'!$D:$D,'💰 Receitas'!$A:$A,">="&DATE('📊 Dashboard'!$L$3,3,1),'💰 Receitas'!$A:$A,"<="&EOMONTH(DATE('📊 Dashboard'!$L$3,3,1),0)) | C10: =SUMIFS('💸 Despesas'!$D:$D,'💸 Despesas'!$A:$A,">="&DATE('📊 Dashboard'!$L$3,3,1),'💸 Despesas'!$A:$A,"<="&EOMONTH(DATE('📊 Dashboard'!$L$3,3,1),0)) | D10: =$B10-$C10 | E10: =$E9+$D10 | G10: Transporte | H10: =SUMIFS('💸 Despesas'!$D:$D,'💸 Despesas'!$C:$C,$G10,'💸 Despesas'!$A:$A,">="&DATE('📊 Dashboard'!$L$3,'📊 Dashboard'!$J$3,1),'💸 Despesas'!$A:$A,"<="&EOMONTH(DATE('📊 Dashboard'!$L$3,'📊 Dashboard'!$J$3,1),0)) | I10: =IFERROR($H10/SUM($H$8:$H$18),0)
A11: Abr | B11: =SUMIFS('💰 Receitas'!$D:$D,'💰 Receitas'!$A:$A,">="&DATE('📊 Dashboard'!$L$3,4,1),'💰 Receitas'!$A:$A,"<="&EOMONTH(DATE('📊 Dashboard'!$L$3,4,1),0)) | C11: =SUMIFS('💸 Despesas'!$D:$D,'💸 Despesas'!$A:$A,">="&DATE('📊 Dashboard'!$L$3,4,1),'💸 Despesas'!$A:$A,"<="&EOMONTH(DATE('📊 Dashboard'!$L$3,4,1),0)) | D11: =$B11-$C11 | E11: =$E10+$D11 | G11: Saúde | H11: =SUMIFS('💸 Despesas'!$D:$D,'💸 Despesas'!$C:$C,$G11,'💸 Despesas'!$A:$A,">="&DATE('📊 Dashboard'!$L$3,'📊 Dashboard'!$J$3,1),'💸 Despesas'!$A:$A,"<="&EOMONTH(DATE('📊 Dashboard'!$L$3,'📊 Dashboard'!$J$3,1),0)) | I11: =IFERROR($H11/SUM($H$8:$H$18),0)
A12: Mai | B12: =SUMIFS('💰 Receitas'!$D:$D,'💰 Receitas'!$A:$A,">="&DATE('📊 Dashboard'!$L$3,5,1),'💰 Receitas'!$A:$A,"<="&EOMONTH(DATE('📊 Dashboard'!$L$3,5,1),0)) | C12: =SUMIFS('💸 Despesas'!$D:$D,'💸 Despesas'!$A:$A,">="&DATE('📊 Dashboard'!$L$3,5,1),'💸 Despesas'!$A:$A,"<="&EOMONTH(DATE('📊 Dashboard'!$L$3,5,1),0)) | D12: =$B12-$C12 | E12: =$E11+$D12 | G12: Educação | H12: =SUMIFS('💸 Despesas'!$D:$D,'💸 Despesas'!$C:$C,$G12,'💸 Despesas'!$A:$A,">="&DATE('📊 Dashboard'!$L$3,'📊 Dashboard'!$J$3,1),'💸 Despesas'!$A:$A,"<="&EOMONTH(DATE('📊 Dashboard'!$L$3,'📊 Dashboard'!$J$3,1),0)) | I12: =IFERROR($H12/SUM($H$8:$H$18),0)
A13: Jun | B13: =SUMIFS('💰 Receitas'!$D:$D,'💰 Receitas'!$A:$A,">="&DATE('📊 Dashboard'!$L$3,6,1),'💰 Receitas'!$A:$A,"<="&EOMONTH(DATE('📊 Dashboard'!$L$3,6,1),0)) | C13: =SUMIFS('💸 Despesas'!$D:$D,'💸 Despesas'!$A:$A,">="&DATE('📊 Dashboard'!$L$3,6,1),'💸 Despesas'!$A:$A,"<="&EOMONTH(DATE('📊 Dashboard'!$L$3,6,1),0)) | D13: =$B13-$C13 | E13: =$E12+$D13 | G13: Lazer | H13: =SUMIFS('💸 Despesas'!$D:$D,'💸 Despesas'!$C:$C,$G13,'💸 Despesas'!$A:$A,">="&DATE('📊 Dashboard'!$L$3,'📊 Dashboard'!$J$3,1),'💸 Despesas'!$A:$A,"<="&EOMONTH(DATE('📊 Dashboard'!$L$3,'📊 Dashboard'!$J$3,1),0)) | I13: =IFERROR($H13/SUM($H$8:$H$18),0)
A14: Jul | B14: =SUMIFS('💰 Receitas'!$D:$D,'💰 Receitas'!$A:$A,">="&DATE('📊 Dashboard'!$L$3,7,1),'💰 Receitas'!$A:$A,"<="&EOMONTH(DATE('📊 Dashboard'!$L$3,7,1),0)) | C14: =SUMIFS('💸 Despesas'!$D:$D,'💸 Despesas'!$A:$A,">="&DATE('📊 Dashboard'!$L$3,7,1),'💸 Despesas'!$A:$A,"<="&EOMONTH(DATE('📊 Dashboard'!$L$3,7,1),0)) | D14: =$B14-$C14 | E14: =$E13+$D14 | G14: Vestuário | H14: =SUMIFS('💸 Despesas'!$D:$D,'💸 Despesas'!$C:$C,$G14,'💸 Despesas'!$A:$A,">="&DATE('📊 Dashboard'!$L$3,'📊 Dashboard'!$J$3,1),'💸 Despesas'!$A:$A,"<="&EOMONTH(DATE('📊 Dashboard'!$L$3,'📊 Dashboard'!$J$3,1),0)) | I14: =IFERROR($H14/SUM($H$8:$H$18),0)
A15: Ago | B15: =SUMIFS('💰 Receitas'!$D:$D,'💰 Receitas'!$A:$A,">="&DATE('📊 Dashboard'!$L$3,8,1),'💰 Receitas'!$A:$A,"<="&EOMONTH(DATE('📊 Dashboard'!$L$3,8,1),0)) | C15: =SUMIFS('💸 Despesas'!$D:$D,'💸 Despesas'!$A:$A,">="&DATE('📊 Dashboard'!$L$3,8,1),'💸 Despesas'!$A:$A,"<="&EOMONTH(DATE('📊 Dashboard'!$L$3,8,1),0)) | D15: =$B15-$C15 | E15: =$E14+$D15 | G15: Assinaturas | H15: =SUMIFS('💸 Despesas'!$D:$D,'💸 Despesas'!$C:$C,$G15,'💸 Despesas'!$A:$A,">="&DATE('📊 Dashboard'!$L$3,'📊 Dashboard'!$J$3,1),'💸 Despesas'!$A:$A,"<="&EOMONTH(DATE('📊 Dashboard'!$L$3,'📊 Dashboard'!$J$3,1),0)) | I15: =IFERROR($H15/SUM($H$8:$H$18),0)
A16: Set | B16: =SUMIFS('💰 Receitas'!$D:$D,'💰 Receitas'!$A:$A,">="&DATE('📊 Dashboard'!$L$3,9,1),'💰 Receitas'!$A:$A,"<="&EOMONTH(DATE('📊 Dashboard'!$L$3,9,1),0)) | C16: =SUMIFS('💸 Despesas'!$D:$D,'💸 Despesas'!$A:$A,">="&DATE('📊 Dashboard'!$L$3,9,1),'💸 Despesas'!$A:$A,"<="&EOMONTH(DATE('📊 Dashboard'!$L$3,9,1),0)) | D16: =$B16-$C16 | E16: =$E15+$D16 | G16: Contas Fixas | H16: =SUMIFS('💸 Despesas'!$D:$D,'💸 Despesas'!$C:$C,$G16,'💸 Despesas'!$A:$A,">="&DATE('📊 Dashboard'!$L$3,'📊 Dashboard'!$J$3,1),'💸 Despesas'!$A:$A,"<="&EOMONTH(DATE('📊 Dashboard'!$L$3,'📊 Dashboard'!$J$3,1),0)) | I16: =IFERROR($H16/SUM($H$8:$H$18),0)
A17: Out | B17: =SUMIFS('💰 Receitas'!$D:$D,'💰 Receitas'!$A:$A,">="&DATE('📊 Dashboard'!$L$3,10,1),'💰 Receitas'!$A:$A,"<="&EOMONTH(DATE('📊 Dashboard'!$L$3,10,1),0)) | C17: =SUMIFS('💸 Despesas'!$D:$D,'💸 Despesas'!$A:$A,">="&DATE('📊 Dashboard'!$L$3,10,1),'💸 Despesas'!$A:$A,"<="&EOMONTH(DATE('📊 Dashboard'!$L$3,10,1),0)) | D17: =$B17-$C17 | E17: =$E16+$D17 | G17: Investimentos | H17: =SUMIFS('💸 Despesas'!$D:$D,'💸 Despesas'!$C:$C,$G17,'💸 Despesas'!$A:$A,">="&DATE('📊 Dashboard'!$L$3,'📊 Dashboard'!$J$3,1),'💸 Despesas'!$A:$A,"<="&EOMONTH(DATE('📊 Dashboard'!$L$3,'📊 Dashboard'!$J$3,1),0)) | I17: =IFERROR($H17/SUM($H$8:$H$18),0)
A18: Nov | B18: =SUMIFS('💰 Receitas'!$D:$D,'💰 Receitas'!$A:$A,">="&DATE('📊 Dashboard'!$L$3,11,1),'💰 Receitas'!$A:$A,"<="&EOMONTH(DATE('📊 Dashboard'!$L$3,11,1),0)) | C18: =SUMIFS('💸 Despesas'!$D:$D,'💸 Despesas'!$A:$A,">="&DATE('📊 Dashboard'!$L$3,11,1),'💸 Despesas'!$A:$A,"<="&EOMONTH(DATE('📊 Dashboard'!$L$3,11,1),0)) | D18: =$B18-$C18 | E18: =$E17+$D18 | G18: Outros | H18: =SUMIFS('💸 Despesas'!$D:$D,'💸 Despesas'!$C:$C,$G18,'💸 Despesas'!$A:$A,">="&DATE('📊 Dashboard'!$L$3,'📊 Dashboard'!$J$3,1),'💸 Despesas'!$A:$A,"<="&EOMONTH(DATE('📊 Dashboard'!$L$3,'📊 Dashboard'!$J$3,1),0)) | I18: =IFERROR($H18/SUM($H$8:$H$18),0)
A19: Dez | B19: =SUMIFS('💰 Receitas'!$D:$D,'💰 Receitas'!$A:$A,">="&DATE('📊 Dashboard'!$L$3,12,1),'💰 Receitas'!$A:$A,"<="&EOMONTH(DATE('📊 Dashboard'!$L$3,12,1),0)) | C19: =SUMIFS('💸 Despesas'!$D:$D,'💸 Despesas'!$A:$A,">="&DATE('📊 Dashboard'!$L$3,12,1),'💸 Despesas'!$A:$A,"<="&EOMONTH(DATE('📊 Dashboard'!$L$3,12,1),0)) | D19: =$B19-$C19 | E19: =$E18+$D19
A20: TOTAL | B20: =SUM(B8:B19) | C20: =SUM(C8:C19) | D20: =SUM(D8:D19)
A22: 🏆 Ranking — 10 maiores despesas lançadas | G22: 📅 Comparativo anual
A23: Nº | B23: Descrição | D23: Valor | G23: Ano | H23: Receitas | I23: Despesas
A24: 1 | B24: =IFERROR(INDEX('💸 Despesas'!$B$5:$B$204,MATCH($D24,'💸 Despesas'!$D$5:$D$204,0)),"") | D24: =IFERROR(LARGE('💸 Despesas'!$D$5:$D$204,1),"") | G24: ='📊 Dashboard'!$L$3-1 | H24: =SUMIFS('💰 Receitas'!$D:$D,'💰 Receitas'!$A:$A,">="&DATE('📊 Dashboard'!$L$3-1,1,1),'💰 Receitas'!$A:$A,"<="&DATE('📊 Dashboard'!$L$3-1,12,31)) | I24: =SUMIFS('💸 Despesas'!$D:$D,'💸 Despesas'!$A:$A,">="&DATE('📊 Dashboard'!$L$3-1,1,1),'💸 Despesas'!$A:$A,"<="&DATE('📊 Dashboard'!$L$3-1,12,31))
A25: 2 | B25: =IFERROR(INDEX('💸 Despesas'!$B$5:$B$204,MATCH($D25,'💸 Despesas'!$D$5:$D$204,0)),"") | D25: =IFERROR(LARGE('💸 Despesas'!$D$5:$D$204,2),"") | G25: ='📊 Dashboard'!$L$3 | H25: =SUMIFS('💰 Receitas'!$D:$D,'💰 Receitas'!$A:$A,">="&DATE('📊 Dashboard'!$L$3,1,1),'💰 Receitas'!$A:$A,"<="&DATE('📊 Dashboard'!$L$3,12,31)) | I25: =SUMIFS('💸 Despesas'!$D:$D,'💸 Despesas'!$A:$A,">="&DATE('📊 Dashboard'!$L$3,1,1),'💸 Despesas'!$A:$A,"<="&DATE('📊 Dashboard'!$L$3,12,31))
A26: 3 | B26: =IFERROR(INDEX('💸 Despesas'!$B$5:$B$204,MATCH($D26,'💸 Despesas'!$D$5:$D$204,0)),"") | D26: =IFERROR(LARGE('💸 Despesas'!$D$5:$D$204,3),"")
A27: 4 | B27: =IFERROR(INDEX('💸 Despesas'!$B$5:$B$204,MATCH($D27,'💸 Despesas'!$D$5:$D$204,0)),"") | D27: =IFERROR(LARGE('💸 Despesas'!$D$5:$D$204,4),"")
A28: 5 | B28: =IFERROR(INDEX('💸 Despesas'!$B$5:$B$204,MATCH($D28,'💸 Despesas'!$D$5:$D$204,0)),"") | D28: =IFERROR(LARGE('💸 Despesas'!$D$5:$D$204,5),"")
A29: 6 | B29: =IFERROR(INDEX('💸 Despesas'!$B$5:$B$204,MATCH($D29,'💸 Despesas'!$D$5:$D$204,0)),"") | D29: =IFERROR(LARGE('💸 Despesas'!$D$5:$D$204,6),"")
A30: 7 | B30: =IFERROR(INDEX('💸 Despesas'!$B$5:$B$204,MATCH($D30,'💸 Despesas'!$D$5:$D$204,0)),"") | D30: =IFERROR(LARGE('💸 Despesas'!$D$5:$D$204,7),"")
A31: 8 | B31: =IFERROR(INDEX('💸 Despesas'!$B$5:$B$204,MATCH($D31,'💸 Despesas'!$D$5:$D$204,0)),"") | D31: =IFERROR(LARGE('💸 Despesas'!$D$5:$D$204,8),"")
A32: 9 | B32: =IFERROR(INDEX('💸 Despesas'!$B$5:$B$204,MATCH($D32,'💸 Despesas'!$D$5:$D$204,0)),"") | D32: =IFERROR(LARGE('💸 Despesas'!$D$5:$D$204,9),"")
A33: 10 | B33: =IFERROR(INDEX('💸 Despesas'!$B$5:$B$204,MATCH($D33,'💸 Despesas'!$D$5:$D$204,0)),"") | D33: =IFERROR(LARGE('💸 Despesas'!$D$5:$D$204,10),"")

Sheet 🔔 Alertas
B1: 📊 Início | C1: 💰 Receitas | D1: 💸 Despesas | E1: 🏦 Contas | F1: 💳 Cartões | G1: 🎯 Metas | H1: 📅 Orçamento | I1: 📈 Relatórios | J1: 🔔 Alertas | K1: ⚙️ Config
B3: 🔔 Alertas Inteligentes
B4: Tudo aqui é automático — os avisos aparecem conforme seus lançamentos.
A6: Resumo
B7: 🚨 Orçamentos estourados no mês | E7: =SUMPRODUCT(('📅 Planejamento'!$C$7:$C$17>'📅 Planejamento'!$B$7:$B$17)*1) | F7: =IF($E7=0,"✅ OK","⚠️ Verificar")
B8: ⏰ Contas a vencer nos próximos 7 dias | E8: =COUNTIFS('💸 Despesas'!$I:$I,"Não",'💸 Despesas'!$H:$H,">="&TODAY(),'💸 Despesas'!$H:$H,"<="&TODAY()+7) | F8: =IF($E8=0,"✅ OK","⚠️ Verificar")
B9: 🔴 Contas vencidas e não pagas | E9: =COUNTIFS('💸 Despesas'!$I:$I,"Não",'💸 Despesas'!$H:$H,"<"&TODAY()) | F9: =IF($E9=0,"✅ OK","⚠️ Verificar")
B10: 🎉 Metas atingidas | E10: =SUMPRODUCT(('🎯 Metas'!$C$7:$C$14>='🎯 Metas'!$B$7:$B$14)*('🎯 Metas'!$B$7:$B$14>0)) | F10: =IF($E10=0,"✅ OK","⚠️ Verificar")
A13: ⏰ Vencimentos próximos (inclui vencidas)
A14: Nº | B14: Vencimento | C14: Descrição | D14: Valor | E14: Dias | F14: Situação
A15: 1 | B15: =IFERROR(INDEX('💸 Despesas'!$H$5:$H$204,MATCH(1,'💸 Despesas'!$K$5:$K$204,0)),"") | C15: =IFERROR(INDEX('💸 Despesas'!$B$5:$B$204,MATCH(1,'💸 Despesas'!$K$5:$K$204,0)),"") | D15: =IFERROR(INDEX('💸 Despesas'!$D$5:$D$204,MATCH(1,'💸 Despesas'!$K$5:$K$204,0)),"") | E15: =IF($B15="","",$B15-TODAY()) | F15: =IF($B15="","",IF($E15<0,"🔴 VENCIDA",IF($E15<=3,"🟠 Urgente","🟡 Em breve")))
A16: 2 | B16: =IFERROR(INDEX('💸 Despesas'!$H$5:$H$204,MATCH(2,'💸 Despesas'!$K$5:$K$204,0)),"") | C16: =IFERROR(INDEX('💸 Despesas'!$B$5:$B$204,MATCH(2,'💸 Despesas'!$K$5:$K$204,0)),"") | D16: =IFERROR(INDEX('💸 Despesas'!$D$5:$D$204,MATCH(2,'💸 Despesas'!$K$5:$K$204,0)),"") | E16: =IF($B16="","",$B16-TODAY()) | F16: =IF($B16="","",IF($E16<0,"🔴 VENCIDA",IF($E16<=3,"🟠 Urgente","🟡 Em breve")))
A17: 3 | B17: =IFERROR(INDEX('💸 Despesas'!$H$5:$H$204,MATCH(3,'💸 Despesas'!$K$5:$K$204,0)),"") | C17: =IFERROR(INDEX('💸 Despesas'!$B$5:$B$204,MATCH(3,'💸 Despesas'!$K$5:$K$204,0)),"") | D17: =IFERROR(INDEX('💸 Despesas'!$D$5:$D$204,MATCH(3,'💸 Despesas'!$K$5:$K$204,0)),"") | E17: =IF($B17="","",$B17-TODAY()) | F17: =IF($B17="","",IF($E17<0,"🔴 VENCIDA",IF($E17<=3,"🟠 Urgente","🟡 Em breve")))
A18: 4 | B18: =IFERROR(INDEX('💸 Despesas'!$H$5:$H$204,MATCH(4,'💸 Despesas'!$K$5:$K$204,0)),"") | C18: =IFERROR(INDEX('💸 Despesas'!$B$5:$B$204,MATCH(4,'💸 Despesas'!$K$5:$K$204,0)),"") | D18: =IFERROR(INDEX('💸 Despesas'!$D$5:$D$204,MATCH(4,'💸 Despesas'!$K$5:$K$204,0)),"") | E18: =IF($B18="","",$B18-TODAY()) | F18: =IF($B18="","",IF($E18<0,"🔴 VENCIDA",IF($E18<=3,"🟠 Urgente","🟡 Em breve")))
A19: 5 | B19: =IFERROR(INDEX('💸 Despesas'!$H$5:$H$204,MATCH(5,'💸 Despesas'!$K$5:$K$204,0)),"") | C19: =IFERROR(INDEX('💸 Despesas'!$B$5:$B$204,MATCH(5,'💸 Despesas'!$K$5:$K$204,0)),"") | D19: =IFERROR(INDEX('💸 Despesas'!$D$5:$D$204,MATCH(5,'💸 Despesas'!$K$5:$K$204,0)),"") | E19: =IF($B19="","",$B19-TODAY()) | F19: =IF($B19="","",IF($E19<0,"🔴 VENCIDA",IF($E19<=3,"🟠 Urgente","🟡 Em breve")))
A20: 6 | B20: =IFERROR(INDEX('💸 Despesas'!$H$5:$H$204,MATCH(6,'💸 Despesas'!$K$5:$K$204,0)),"") | C20: =IFERROR(INDEX('💸 Despesas'!$B$5:$B$204,MATCH(6,'💸 Despesas'!$K$5:$K$204,0)),"") | D20: =IFERROR(INDEX('💸 Despesas'!$D$5:$D$204,MATCH(6,'💸 Despesas'!$K$5:$K$204,0)),"") | E20: =IF($B20="","",$B20-TODAY()) | F20: =IF($B20="","",IF($E20<0,"🔴 VENCIDA",IF($E20<=3,"🟠 Urgente","🟡 Em breve")))
A21: 7 | B21: =IFERROR(INDEX('💸 Despesas'!$H$5:$H$204,MATCH(7,'💸 Despesas'!$K$5:$K$204,0)),"") | C21: =IFERROR(INDEX('💸 Despesas'!$B$5:$B$204,MATCH(7,'💸 Despesas'!$K$5:$K$204,0)),"") | D21: =IFERROR(INDEX('💸 Despesas'!$D$5:$D$204,MATCH(7,'💸 Despesas'!$K$5:$K$204,0)),"") | E21: =IF($B21="","",$B21-TODAY()) | F21: =IF($B21="","",IF($E21<0,"🔴 VENCIDA",IF($E21<=3,"🟠 Urgente","🟡 Em breve")))
A22: 8 | B22: =IFERROR(INDEX('💸 Despesas'!$H$5:$H$204,MATCH(8,'💸 Despesas'!$K$5:$K$204,0)),"") | C22: =IFERROR(INDEX('💸 Despesas'!$B$5:$B$204,MATCH(8,'💸 Despesas'!$K$5:$K$204,0)),"") | D22: =IFERROR(INDEX('💸 Despesas'!$D$5:$D$204,MATCH(8,'💸 Despesas'!$K$5:$K$204,0)),"") | E22: =IF($B22="","",$B22-TODAY()) | F22: =IF($B22="","",IF($E22<0,"🔴 VENCIDA",IF($E22<=3,"🟠 Urgente","🟡 Em breve")))
A23: 9 | B23: =IFERROR(INDEX('💸 Despesas'!$H$5:$H$204,MATCH(9,'💸 Despesas'!$K$5:$K$204,0)),"") | C23: =IFERROR(INDEX('💸 Despesas'!$B$5:$B$204,MATCH(9,'💸 Despesas'!$K$5:$K$204,0)),"") | D23: =IFERROR(INDEX('💸 Despesas'!$D$5:$D$204,MATCH(9,'💸 Despesas'!$K$5:$K$204,0)),"") | E23: =IF($B23="","",$B23-TODAY()) | F23: =IF($B23="","",IF($E23<0,"🔴 VENCIDA",IF($E23<=3,"🟠 Urgente","🟡 Em breve")))
A24: 10 | B24: =IFERROR(INDEX('💸 Despesas'!$H$5:$H$204,MATCH(10,'💸 Despesas'!$K$5:$K$204,0)),"") | C24: =IFERROR(INDEX('💸 Despesas'!$B$5:$B$204,MATCH(10,'💸 Despesas'!$K$5:$K$204,0)),"") | D24: =IFERROR(INDEX('💸 Despesas'!$D$5:$D$204,MATCH(10,'💸 Despesas'!$K$5:$K$204,0)),"") | E24: =IF($B24="","",$B24-TODAY()) | F24: =IF($B24="","",IF($E24<0,"🔴 VENCIDA",IF($E24<=3,"🟠 Urgente","🟡 Em breve")))
A27: 🚨 Orçamentos estourados (mês selecionado)
B28: Categoria | C28: Estouro (R$)
B29: =IF('📅 Planejamento'!$C$7>'📅 Planejamento'!$B$7,'📅 Planejamento'!$A$7,"") | C29: =IF('📅 Planejamento'!$C$7>'📅 Planejamento'!$B$7,'📅 Planejamento'!$C$7-'📅 Planejamento'!$B$7,"")
B30: =IF('📅 Planejamento'!$C$8>'📅 Planejamento'!$B$8,'📅 Planejamento'!$A$8,"") | C30: =IF('📅 Planejamento'!$C$8>'📅 Planejamento'!$B$8,'📅 Planejamento'!$C$8-'📅 Planejamento'!$B$8,"")
B31: =IF('📅 Planejamento'!$C$9>'📅 Planejamento'!$B$9,'📅 Planejamento'!$A$9,"") | C31: =IF('📅 Planejamento'!$C$9>'📅 Planejamento'!$B$9,'📅 Planejamento'!$C$9-'📅 Planejamento'!$B$9,"")
B32: =IF('📅 Planejamento'!$C$10>'📅 Planejamento'!$B$10,'📅 Planejamento'!$A$10,"") | C32: =IF('📅 Planejamento'!$C$10>'📅 Planejamento'!$B$10,'📅 Planejamento'!$C$10-'📅 Planejamento'!$B$10,"")
B33: =IF('📅 Planejamento'!$C$11>'📅 Planejamento'!$B$11,'📅 Planejamento'!$A$11,"") | C33: =IF('📅 Planejamento'!$C$11>'📅 Planejamento'!$B$11,'📅 Planejamento'!$C$11-'📅 Planejamento'!$B$11,"")
B34: =IF('📅 Planejamento'!$C$12>'📅 Planejamento'!$B$12,'📅 Planejamento'!$A$12,"") | C34: =IF('📅 Planejamento'!$C$12>'📅 Planejamento'!$B$12,'📅 Planejamento'!$C$12-'📅 Planejamento'!$B$12,"")
B35: =IF('📅 Planejamento'!$C$13>'📅 Planejamento'!$B$13,'📅 Planejamento'!$A$13,"") | C35: =IF('📅 Planejamento'!$C$13>'📅 Planejamento'!$B$13,'📅 Planejamento'!$C$13-'📅 Planejamento'!$B$13,"")
B36: =IF('📅 Planejamento'!$C$14>'📅 Planejamento'!$B$14,'📅 Planejamento'!$A$14,"") | C36: =IF('📅 Planejamento'!$C$14>'📅 Planejamento'!$B$14,'📅 Planejamento'!$C$14-'📅 Planejamento'!$B$14,"")
B37: =IF('📅 Planejamento'!$C$15>'📅 Planejamento'!$B$15,'📅 Planejamento'!$A$15,"") | C37: =IF('📅 Planejamento'!$C$15>'📅 Planejamento'!$B$15,'📅 Planejamento'!$C$15-'📅 Planejamento'!$B$15,"")
B38: =IF('📅 Planejamento'!$C$16>'📅 Planejamento'!$B$16,'📅 Planejamento'!$A$16,"") | C38: =IF('📅 Planejamento'!$C$16>'📅 Planejamento'!$B$16,'📅 Planejamento'!$C$16-'📅 Planejamento'!$B$16,"")
B39: =IF('📅 Planejamento'!$C$17>'📅 Planejamento'!$B$17,'📅 Planejamento'!$A$17,"") | C39: =IF('📅 Planejamento'!$C$17>'📅 Planejamento'!$B$17,'📅 Planejamento'!$C$17-'📅 Planejamento'!$B$17,"")
A42: 🎉 Metas atingidas
B43: =IF(AND('🎯 Metas'!$B$7>0,'🎯 Metas'!$C$7>='🎯 Metas'!$B$7),"🎉 Parabéns! Meta """&'🎯 Metas'!$A$7&""" atingida!","")
B44: =IF(AND('🎯 Metas'!$B$8>0,'🎯 Metas'!$C$8>='🎯 Metas'!$B$8),"🎉 Parabéns! Meta """&'🎯 Metas'!$A$8&""" atingida!","")
B45: =IF(AND('🎯 Metas'!$B$9>0,'🎯 Metas'!$C$9>='🎯 Metas'!$B$9),"🎉 Parabéns! Meta """&'🎯 Metas'!$A$9&""" atingida!","")
B46: =IF(AND('🎯 Metas'!$B$10>0,'🎯 Metas'!$C$10>='🎯 Metas'!$B$10),"🎉 Parabéns! Meta """&'🎯 Metas'!$A$10&""" atingida!","")
B47: =IF(AND('🎯 Metas'!$B$11>0,'🎯 Metas'!$C$11>='🎯 Metas'!$B$11),"🎉 Parabéns! Meta """&'🎯 Metas'!$A$11&""" atingida!","")
B48: =IF(AND('🎯 Metas'!$B$12>0,'🎯 Metas'!$C$12>='🎯 Metas'!$B$12),"🎉 Parabéns! Meta """&'🎯 Metas'!$A$12&""" atingida!","")
...

Sheet ⚙️ Config
B1: 📊 Início | C1: 💰 Receitas | D1: 💸 Despesas | E1: 🏦 Contas | F1: 💳 Cartões | G1: 🎯 Metas | H1: 📅 Orçamento | I1: 📈 Relatórios | J1: 🔔 Alertas | K1: ⚙️ Config
B3: ⚙️ Configurações
B4: Listas usadas nas validações — edite à vontade.
B6: Categorias de Receita | C6: Categorias de Despesa | D6: Formas de Pagamento | E6: Contas / Bancos | F6: Cartões | G6: Mês (nº) | H6: Mês (nome) | I6: Anos
B7: Salário | C7: Moradia | D7: Dinheiro | E7: Itaú | F7: Nubank | G7: 1 | H7: Janeiro | I7: 2024
B8: Freelance | C8: Alimentação | D8: Pix | E8: Nubank | F8: Itaú | G8: 2 | H8: Fevereiro | I8: 2025
B9: Investimentos | C9: Transporte | D9: Débito | E9: Caixa | F9: Inter | G9: 3 | H9: Março | I9: 2026
B10: Vendas | C10: Saúde | D10: Crédito | E10: Inter | G10: 4 | H10: Abril | I10: 2027
B11: Aluguel | C11: Educação | D11: Boleto | E11: Carteira | G11: 5 | H11: Maio | I11: 2028
B12: Reembolso | C12: Lazer | D12: Transferência | G12: 6 | H12: Junho | I12: 2029
B13: Outros | C13: Vestuário | G13: 7 | H13: Julho | I13: 2030
C14: Assinaturas | G14: 8 | H14: Agosto | I14: 2031
C15: Contas Fixas | G15: 9 | H15: Setembro
C16: Investimentos | G16: 10 | H16: Outubro
C17: Outros | G17: 11 | H17: Novembro
G18: 12 | H18: Dezembro
B27: 💡 Como usar
B28: 1. Lance suas receitas e despesas nas abas 💰 e 💸 (use os menus suspensos).
B29: 2. Escolha o mês e o ano no topo do 📊 Dashboard — tudo recalcula sozinho.
B30: 3. Cadastre bancos em 🏦 Contas e cartões em 💳 Cartões.
B31: 4. Defina orçamentos em 📅 Planejamento e metas em 🎯 Metas.
B32: 5. A aba 🔔 Alertas avisa sobre vencimentos, estouros e metas atingidas.
B33: 6. As fórmulas estão protegidas (sem senha): Revisão ▸ Desproteger Planilha.
